<?xml version="1.0" ?>
<robot xmlns:xacro="http://www.ros.org/wiki/xacro">

  <xacro:macro name="m_joint" params="name type axis_xyz origin_rpy origin_xyz parent child limit_e limit_l limit_u limit_v">
    <joint name="${name}" type="${type}">
      <axis xyz="${axis_xyz}" />
      <limit effort="${limit_e}" lower="${limit_l}" upper="${limit_u}" velocity="${limit_v}" />
      <origin rpy="${origin_rpy}" xyz="${origin_xyz}" />
      <parent link="${parent}" />
      <child link="${child}" />
    </joint>
    <transmission name="trans_${name}">
      <type>transmission_interface/SimpleTransmission</type>
      <joint name="${name}">
        <hardwareInterface>hardware_interface/EffortJointInterface</hardwareInterface>
      </joint>
      <actuator name="motor_${name}">
        <hardwareInterface>hardware_interface/EffortJointInterface</hardwareInterface>
        <mechanicalReduction>1</mechanicalReduction>
      </actuator>
    </transmission>
  </xacro:macro>

  <xacro:macro name="m_link_cylinder" params="name origin_xyz origin_rpy radius length mass ixx ixy ixz iyy iyz izz">
    <link name="${name}">
      <inertial>
        <mass value="${mass}" />
        <origin rpy="${origin_rpy}" xyz="${origin_xyz}" />
        <inertia ixx="${ixx}" ixy="${ixy}" ixz="${ixz}" iyy="${iyy}" iyz="${iyz}" izz="${izz}" />
      </inertial>
      <collision>
        <origin rpy="${origin_rpy}" xyz="${origin_xyz}" />
        <geometry>
          <cylinder radius="${radius}" length="${length}" />
        </geometry>
      </collision>
      <visual>
        <origin rpy="${origin_rpy}" xyz="${origin_xyz}" />
        <geometry>
          <cylinder radius="${radius}" length="${length}" />
        </geometry>
      </visual>
    </link>
  </xacro:macro>

  <xacro:macro name="m_link_box" params="name origin_xyz origin_rpy size mass ixx ixy ixz iyy iyz izz">
    <link name="${name}">
      <inertial>
        <mass value="${mass}" />
        <origin rpy="${origin_rpy}" xyz="${origin_xyz}" />
        <inertia ixx="${ixx}" ixy="${ixy}" ixz="${ixz}" iyy="${iyy}" iyz="${iyz}" izz="${izz}" />
      </inertial>
      <collision>
        <origin rpy="${origin_rpy}" xyz="${origin_xyz}" />
        <geometry>
          <box size="${size}" />
        </geometry>
      </collision>
      <visual>
        <origin rpy="${origin_rpy}" xyz="${origin_xyz}" />
        <geometry>
          <box size="${size}" />
        </geometry>
      </visual>
    </link>
  </xacro:macro>

  <xacro:macro name="m_link_mesh" params="name origin_xyz origin_rpy meshfile meshscale mass ixx ixy ixz iyy iyz izz">
    <link name="${name}">
      <inertial>
        <mass value="${mass}" />
        <origin rpy="${origin_rpy}" xyz="${origin_xyz}" />
        <inertia ixx="${ixx}" ixy="${ixy}" ixz="${ixz}" iyy="${iyy}" iyz="${iyz}" izz="${izz}" />
      </inertial>
      <collision>
        <origin rpy="${origin_rpy}" xyz="${origin_xyz}" />
        <geometry>
          <mesh filename="${meshfile}" scale="${meshscale}"/>
        </geometry>
      </collision>
      <visual>
        <origin rpy="${origin_rpy}" xyz="${origin_xyz}" />
        <geometry>
          <mesh filename="${meshfile}" scale="${meshscale}"/>
        </geometry>
        <material name="light_black"/>
      </visual>
    </link>
  </xacro:macro>

  <!-- Gripper -->

  <xacro:macro name="default_inertial" params="mass">
      <inertial>
        <mass value="${mass}" />
        <inertia ixx="${1e-3}" ixy="0.0" ixz="0.0" iyy="${1e-3}" iyz="0.0" izz="${1e-3}" />
      </inertial>
  </xacro:macro>

  <xacro:macro name="gripper" params="prefix reflect">
    <joint name="${prefix}_gripper_joint" type="revolute">
      <axis xyz="0 0 1"/>
      <limit effort="1000.0" lower="0.0" upper="0.548" velocity="0.5"/>
      <origin rpy="0  -1.57 ${(1-reflect)/2*3.14}" xyz="0 ${reflect*0.025} 0.8"/>
      <parent link="${link_03_name}"/>
      <child link="${prefix}_gripper"/>
    </joint>
    <transmission name="trans_${prefix}_gripper">
      <type>transmission_interface/SimpleTransmission</type>
      <joint name="${prefix}_gripper_joint">
        <hardwareInterface>hardware_interface/PositionJointInterface</hardwareInterface>
      </joint>
      <actuator name="motor_${prefix}_gripper">
        <hardwareInterface>hardware_interface/PositionJointInterface</hardwareInterface>
        <mechanicalReduction>1</mechanicalReduction>
      </actuator>
    </transmission>
    <link name="${prefix}_gripper">
      <visual>
        <origin rpy="0 0 0" xyz="0 0 0"/>
        <geometry>
          <mesh filename="package://AJTemplateBot/meshes/l_finger.dae" scale="2.5 2.5 2.5"/>
        </geometry>
      </visual>
      <collision>
        <geometry>
          <mesh filename="package://AJTemplateBot/meshes/l_finger.dae" scale="2.5 2.5 2.5"/>
        </geometry>
        <origin rpy="0 0 0" xyz="0 0 0"/>
      </collision>
      <xacro:default_inertial mass="0.05"/>
    </link>

    <joint name="${prefix}_tip_joint" type="fixed">
      <parent link="${prefix}_gripper"/>
      <child link="${prefix}_tip"/>
    </joint>
    <link name="${prefix}_tip">
      <visual>
        <origin rpy="0 0 0" xyz="${2.5*0.09137} ${2.5*0.00495} 0"/>
        <geometry>
          <mesh filename="package://AJTemplateBot/meshes/l_finger_tip.dae" scale="2.5 2.5 2.5"/>
        </geometry>
      </visual>
      <collision>
        <geometry>
          <mesh filename="package://AJTemplateBot/meshes/l_finger_tip.dae" scale="2.5 2.5 2.5"/>
        </geometry>
        <origin rpy="0 0 0" xyz="${2.5*0.09137} ${2.5*0.00495} 0"/>
      </collision>
      <xacro:default_inertial mass="0.05"/>
    </link>
  </xacro:macro>




</robot>
